Workbook
Name Slicer_Brand: #N/A
Name Slicer_Country: #N/A
Name Slicer_Date: #N/A
Name Slicer_Sales_Channel: #N/A

Sheet Data Cleaning
A1: Sale_ID | B1: Date | C1: Brand | D1: Shoe_Type | E1: Color | F1: Country | G1: Sales_Channel | H1: Price_USD | I1: Units_Sold | J1: Revenue_USD | L1: Outlier Limit (Price_USD) | Q1: Column Name | R1: Number of Data | S1: Missing Values | T1: Type of Data | U1: Duplicate Data
A2: S1 | B2: 45985 | C2: Nike | D2: Boots | E2: Blue | F2: UK | G2: Online | H2: 112.4 | I2: 4 | J2: 449.6 | L2: Q1 | M2: =_xlfn.QUARTILE.INC('Data Cleaning'!$H$2:$H$1007,1) -> 81.365 | Q2: Sale_ID | R2: =COUNTA(INDEX($A$2:$J$1007,0,MATCH(Q2,$A$1:$J$1,0))) -> 1006 | S2: =COUNTBLANK(INDEX($A$2:$J$1007,0,MATCH(Q2,$A$1:$J$1,0))) -> 0 | T2: =IF(TYPE(INDEX($A$2:$J$1007,0,MATCH(Q2,$A$1:$J$1,0)))=1,"NUMBER", IF(TYPE(INDEX($A$2:$J$1007,0,MATCH(Q2,$A$1:$J$1,0)))=2,"TEXT", IF(TYPE(INDEX($A$2:$J$1007,0,MATCH(Q2,$A$1:$J$1,0)))=4,"LOGICAL", IF(TYPE(INDEX($A$2:$J$1007,0,MATCH(Q2,$A$1:$J$1,0)))=16,"ERROR", "LAINNYA")))) -> TEXT | U2: Use of Conditional Formatting: to identify duplicate data. In this dataset, the Sale_ID column should contain unique values. The results showed that no duplicate data was detected in the Sale_ID.
A3: S2 | B3: 45729 | C3: Skechers | D3: Boots | E3: Grey | F3: USA | G3: Mall | H3: 239.16 | I3: 4 | J3: 956.64 | L3: Q3 | M3: =_xlfn.QUARTILE.INC('Data Cleaning'!$H$2:$H$1007,3) -> 193.515 | Q3: Date | R3: =COUNTA(INDEX($A$2:$J$1007,0,MATCH(Q3,$A$1:$J$1,0))) -> 1006 | S3: =COUNTBLANK(INDEX($A$2:$J$1007,0,MATCH(Q3,$A$1:$J$1,0))) -> 0 | T3: =IF(TYPE(INDEX($A$2:$J$1007,0,MATCH(Q3,$A$1:$J$1,0)))=1,"DATE", IF(TYPE(INDEX($A$2:$J$1007,0,MATCH(Q3,$A$1:$J$1,0)))=2,"TEXT", IF(TYPE(INDEX($A$2:$J$1007,0,MATCH(Q3,$A$1:$J$1,0)))=4,"LOGICAL", IF(TYPE(INDEX($A$2:$J$1007,0,MATCH(Q3,$A$1:$J$1,0)))=16,"ERROR", "LAINNYA")))) -> DATE
A4: S3 | B4: 45874 | C4: Nike | D4: Running | E4: White | F4: UK | G4: Mall | H4: 191.04 | I4: 2 | J4: 382.08 | L4: IQR | M4: =M3-M2 -> 112.15 | Q4: Brand | R4: =COUNTA(INDEX($A$2:$J$1007,0,MATCH(Q4,$A$1:$J$1,0))) -> 1006 | S4: =COUNTBLANK(INDEX($A$2:$J$1007,0,MATCH(Q4,$A$1:$J$1,0))) -> 0 | T4: =IF(TYPE(INDEX($A$2:$J$1007,0,MATCH(Q4,$A$1:$J$1,0)))=1,"NUMBER", IF(TYPE(INDEX($A$2:$J$1007,0,MATCH(Q4,$A$1:$J$1,0)))=2,"TEXT", IF(TYPE(INDEX($A$2:$J$1007,0,MATCH(Q4,$A$1:$J$1,0)))=4,"LOGICAL", IF(TYPE(INDEX($A$2:$J$1007,0,MATCH(Q4,$A$1:$J$1,0)))=16,"ERROR", "LAINNYA")))) -> TEXT
A5: S4 | B5: 45966 | C5: New Balance | D5: Casual | E5: Green | F5: UAE | G5: Mall | H5: 161.7 | I5: 1 | J5: 161.7 | L5: Lower | M5: =M2-1.5*M4 -> -86.86 | Q5: Shoe_Type | R5: =COUNTA(INDEX($A$2:$J$1007,0,MATCH(Q5,$A$1:$J$1,0))) -> 1006 | S5: =COUNTBLANK(INDEX($A$2:$J$1007,0,MATCH(Q5,$A$1:$J$1,0))) -> 0 | T5: =IF(TYPE(INDEX($A$2:$J$1007,0,MATCH(Q5,$A$1:$J$1,0)))=1,"NUMBER", IF(TYPE(INDEX($A$2:$J$1007,0,MATCH(Q5,$A$1:$J$1,0)))=2,"TEXT", IF(TYPE(INDEX($A$2:$J$1007,0,MATCH(Q5,$A$1:$J$1,0)))=4,"LOGICAL", IF(TYPE(INDEX($A$2:$J$1007,0,MATCH(Q5,$A$1:$J$1,0)))=16,"ERROR", "LAINNYA")))) -> TEXT
A6: S5 | B6: 45937 | C6: Adidas | D6: Formal | E6: Grey | F6: France | G6: Online | H6: 64.32 | I6: 14 | J6: 900.48 | L6: Upper | M6: =M3+1.5*M4 -> 361.74 | Q6: Color | R6: =COUNTA(INDEX($A$2:$J$1007,0,MATCH(Q6,$A$1:$J$1,0))) -> 1006 | S6: =COUNTBLANK(INDEX($A$2:$J$1007,0,MATCH(Q6,$A$1:$J$1,0))) -> 0 | T6: =IF(TYPE(INDEX($A$2:$J$1007,0,MATCH(Q6,$A$1:$J$1,0)))=1,"NUMBER", IF(TYPE(INDEX($A$2:$J$1007,0,MATCH(Q6,$A$1:$J$1,0)))=2,"TEXT", IF(TYPE(INDEX($A$2:$J$1007,0,MATCH(Q6,$A$1:$J$1,0)))=4,"LOGICAL", IF(TYPE(INDEX($A$2:$J$1007,0,MATCH(Q6,$A$1:$J$1,0)))=16,"ERROR", "LAINNYA")))) -> TEXT
A7: S6 | B7: 45739 | C7: Puma | D7: Sports | E7: White | F7: UK | G7: Retail Store | H7: 64.32 | I7: 14 | J7: 900.48 | Q7: Country | R7: =COUNTA(INDEX($A$2:$J$1007,0,MATCH(Q7,$A$1:$J$1,0))) -> 1006 | S7: =COUNTBLANK(INDEX($A$2:$J$1007,0,MATCH(Q7,$A$1:$J$1,0))) -> 0 | T7: =IF(TYPE(INDEX($A$2:$J$1007,0,MATCH(Q7,$A$1:$J$1,0)))=1,"NUMBER", IF(TYPE(INDEX($A$2:$J$1007,0,MATCH(Q7,$A$1:$J$1,0)))=2,"TEXT", IF(TYPE(INDEX($A$2:$J$1007,0,MATCH(Q7,$A$1:$J$1,0)))=4,"LOGICAL", IF(TYPE(INDEX($A$2:$J$1007,0,MATCH(Q7,$A$1:$J$1,0)))=16,"ERROR", "LAINNYA")))) -> TEXT
A8: S7 | B8: 45710 | C8: Reebok | D8: Running | E8: Blue | F8: Saudi Arabia | G8: Retail Store | H8: 42.78 | I8: 3 | J8: 128.34 | L8: Outlier Limit (Units_Sold) | Q8: Sales_Channel | R8: =COUNTA(INDEX($A$2:$J$1007,0,MATCH(Q8,$A$1:$J$1,0))) -> 1006 | S8: =COUNTBLANK(INDEX($A$2:$J$1007,0,MATCH(Q8,$A$1:$J$1,0))) -> 0 | T8: =IF(TYPE(INDEX($A$2:$J$1007,0,MATCH(Q8,$A$1:$J$1,0)))=1,"NUMBER", IF(TYPE(INDEX($A$2:$J$1007,0,MATCH(Q8,$A$1:$J$1,0)))=2,"TEXT", IF(TYPE(INDEX($A$2:$J$1007,0,MATCH(Q8,$A$1:$J$1,0)))=4,"LOGICAL", IF(TYPE(INDEX($A$2:$J$1007,0,MATCH(Q8,$A$1:$J$1,0)))=16,"ERROR", "LAINNYA")))) -> TEXT
A9: S8 | B9: 45967 | C9: Nike | D9: Boots | E9: Red | F9: India | G9: Online | H9: 220.56 | I9: 9 | J9: 1985.04 | L9: Q1 | M9: =_xlfn.QUARTILE.INC('Data Cleaning'!$I$2:$I$1007,1) -> 6 | Q9: Price_USD | R9: =COUNTA(INDEX($A$2:$J$1007,0,MATCH(Q9,$A$1:$J$1,0))) -> 1006 | S9: =COUNTBLANK(INDEX($A$2:$J$1007,0,MATCH(Q9,$A$1:$J$1,0))) -> 0 | T9: =IF(TYPE(INDEX($A$2:$J$1007,0,MATCH(Q9,$A$1:$J$1,0)))=1,"NUMBER", IF(TYPE(INDEX($A$2:$J$1007,0,MATCH(Q9,$A$1:$J$1,0)))=2,"TEXT", IF(TYPE(INDEX($A$2:$J$1007,0,MATCH(Q9,$A$1:$J$1,0)))=4,"LOGICAL", IF(TYPE(INDEX($A$2:$J$1007,0,MATCH(Q9,$A$1:$J$1,0)))=16,"ERROR", "LAINNYA")))) -> NUMBER
A10: S9 | B10: 45851 | C10: New Balance | D10: Sports | E10: Green | F10: India | G10: Retail Store | H10: 162.25 | I10: 3 | J10: 486.75 | L10: Q3 | M10: =_xlfn.QUARTILE.INC('Data Cleaning'!$I$2:$I$1007,3) -> 16 | Q10: Units_Sold | R10: =COUNTA(INDEX($A$2:$J$1007,0,MATCH(Q10,$A$1:$J$1,0))) -> 1006 | S10: =COUNTBLANK(INDEX($A$2:$J$1007,0,MATCH(Q10,$A$1:$J$1,0))) -> 0 | T10: =IF(TYPE(INDEX($A$2:$J$1007,0,MATCH(Q10,$A$1:$J$1,0)))=1,"NUMBER", IF(TYPE(INDEX($A$2:$J$1007,0,MATCH(Q10,$A$1:$J$1,0)))=2,"TEXT", IF(TYPE(INDEX($A$2:$J$1007,0,MATCH(Q10,$A$1:$J$1,0)))=4,"LOGICAL", IF(TYPE(INDEX($A$2:$J$1007,0,MATCH(Q10,$A$1:$J$1,0)))=16,"ERROR", "LAINNYA")))) -> NUMBER
A11: S10 | B11: 45953 | C11: Skechers | D11: Running | E11: Black | F11: UAE | G11: Online | H11: 185.78 | I11: 7 | J11: 1300.46 | L11: IQR | M11: =M10-M9 -> 10 | Q11: Revenue_USD | R11: =COUNTA(INDEX($A$2:$J$1007,0,MATCH(Q11,$A$1:$J$1,0))) -> 1006 | S11: =COUNTBLANK(INDEX($A$2:$J$1007,0,MATCH(Q11,$A$1:$J$1,0))) -> 0 | T11: =IF(TYPE(INDEX($A$2:$J$1007,0,MATCH(Q11,$A$1:$J$1,0)))=1,"NUMBER", IF(TYPE(INDEX($A$2:$J$1007,0,MATCH(Q11,$A$1:$J$1,0)))=2,"TEXT", IF(TYPE(INDEX($A$2:$J$1007,0,MATCH(Q11,$A$1:$J$1,0)))=4,"LOGICAL", IF(TYPE(INDEX($A$2:$J$1007,0,MATCH(Q11,$A$1:$J$1,0)))=16,"ERROR", "LAINNYA")))) -> NUMBER
A12: S11 | B12: 45806 | C12: Adidas | D12: Running | E12: Red | F12: France | G12: Retail Store | H12: 34.53 | I12: 3 | J12: 103.59 | L12: Lower | M12: =M9-1.5*M11 -> -9
A13: S12 | B13: 45983 | C13: Adidas | D13: Sports | E13: Blue | F13: UK | G13: Mall | H13: 243.38 | I13: 12 | J13: 2920.56 | L13: Upper | M13: =M10+1.5*M11 -> 31
A14: S13 | B14: 45794 | C14: New Balance | D14: Boots | E14: White | F14: India | G14: Mall | H14: 213.14 | I14: 3 | J14: 639.42
A15: S14 | B15: 45783 | C15: Reebok | D15: Formal | E15: Blue | F15: UAE | G15: Mall | H15: 76.71 | I15: 6 | J15: 460.26 | L15: Outlier Limit(Revenue_USD)
A16: S15 | B16: 45943 | C16: Skechers | D16: Sports | E16: Black | F16: UK | G16: Online | H16: 70 | I16: 8 | J16: 560 | L16: Q1 | M16: =_xlfn.QUARTILE.INC('Data Cleaning'!$J$2:$J$1007,1) -> 560.35
A17: S16 | B17: 45819 | C17: Puma | D17: Running | E17: White | F17: India | G17: Mall | H17: 70.35 | I17: 13 | J17: 914.55 | L17: Q3 | M17: =_xlfn.QUARTILE.INC('Data Cleaning'!$J$2:$J$1007,3) -> 2161.29
A18: S17 | B18: 45819 | C18: Skechers | D18: Formal | E18: Red | F18: UAE | G18: Retail Store | H18: 96.93 | I18: 7 | J18: 678.51 | L18: IQR | M18: =M17-M16 -> 1600.94
A19: S18 | B19: 45731 | C19: Adidas | D19: Casual | E19: Green | F19: India | G19: Mall | H19: 145.45 | I19: 9 | J19: 1309.05 | L19: Lower | M19: =M16-1.5*M18 -> -1841.06
A20: S19 | B20: 45792 | C20: Reebok | D20: Sneakers | E20: Red | F20: France | G20: Online | H20: 125.03 | I20: 19 | J20: 2375.57 | L20: Upper | M20: =M17+1.5*M18 -> 4562.7
A21: S20 | B21: 45728 | C21: Reebok | D21: Running | E21: Black | F21: Saudi Arabia | G21: Online | H21: 94.07 | I21: 17 | J21: 1599.19
A22: S21 | B22: 45736 | C22: Skechers | D22: Formal | E22: Grey | F22: USA | G22: Retail Store | H22: 164.61 | I22: 6 | J22: 987.66
A23: S22 | B23: 45853 | C23: Reebok | D23: Sneakers | E23: Blue | F23: India | G23: Online | H23: 60.69 | I23: 20 | J23: 1213.8
A24: S23 | B24: 46006 | C24: Skechers | D24: Sneakers | E24: Blue | F24: Saudi Arabia | G24: Mall | H24: 94.27 | I24: 4 | J24: 377.08
A25: S24 | B25: 45832 | C25: Puma | D25: Formal | E25: White | F25: Germany | G25: Online | H25: 110.6 | I25: 4 | J25: 442.4
A26: S25 | B26: 45792 | C26: Adidas | D26: Sneakers | E26: Black | F26: Saudi Arabia | G26: Mall | H26: 130.34 | I26: 17 | J26: 2215.78
A27: S26 | B27: 45810 | C27: New Balance | D27: Casual | E27: White | F27: France | G27: Online | H27: 202.74 | I27: 17 | J27: 3446.58
A28: S27 | B28: 45934 | C28: Nike | D28: Sneakers | E28: Blue | F28: Germany | G28: Online | H28: 73.93 | I28: 17 | J28: 1256.81 | M28: =SUM(J2:J1007)/COUNTA(A2:A1007) -> 1451.1418
A29: S28 | B29: 45715 | C29: Puma | D29: Casual | E29: Black | F29: UK | G29: Mall | H29: 143.13 | I29: 12 | J29: 1717.56
A30: S29 | B30: 45698 | C30: Skechers | D30: Formal | E30: Black | F30: Saudi Arabia | G30: Mall | H30: 160.33 | I30: 3 | J30: 480.99
A31: S30 | B31: 45722 | C31: Skechers | D31: Formal | E31: Grey | F31: UK | G31: Retail Store | H31: 40.22 | I31: 5 | J31: 201.1
A32: S31 | B32: 45928 | C32: Reebok | D32: Casual | E32: Grey | F32: Saudi Arabia | G32: Mall | H32: 163.66 | I32: 20 | J32: 3273.2
A33: S32 | B33: 46011 | C33: Skechers | D33: Sports | E33: Red | F33: UAE | G33: Mall | H33: 67.52 | I33: 7 | J33: 472.64
A34: S33 | B34: 45849 | C34: New Balance | D34: Formal | E34: Black | F34: UK | G34: Online | H34: 44.31 | I34: 15 | J34: 664.65
A35: S34 | B35: 45690 | C35: Nike | D35: Sneakers | E35: Grey | F35: UK | G35: Mall | H35: 238.75 | I35: 11 | J35: 2626.25
A36: S35 | B36: 45770 | C36: Nike | D36: Boots | E36: Green | F36: USA | G36: Online | H36: 242.44 | I36: 1 | J36: 242.44
A37: S36 | B37: 45692 | C37: Puma | D37: Running | E37: Grey | F37: UK | G37: Retail Store | H37: 207.85 | I37: 2 | J37: 415.7
A38: S37 | B38: 46000 | C38: Adidas | D38: Sneakers | E38: White | F38: UAE | G38: Mall | H38: 97.02 | I38: 16 | J38: 1552.32
A39: S38 | B39: 45953 | C39: Adidas | D39: Formal | E39: Red | F39: UK | G39: Online | H39: 51.49 | I39: 16 | J39: 823.84
A40: S39 | B40: 45707 | C40: Puma | D40: Formal | E40: Red | F40: Germany | G40: Mall | H40: 180.53 | I40: 14 | J40: 2527.42
...

Sheet Clean_Dataset
A1: Sale_ID | B1: Date | C1: Brand | D1: Shoe_Type | E1: Color | F1: Country | G1: Sales_Channel | H1: Price_USD | I1: Units_Sold | J1: Revenue_USD
A2: ='Data Cleaning'!A2 -> S1 | B2: ='Data Cleaning'!B2 -> 45985 | C2: ='Data Cleaning'!C2 -> Nike | D2: ='Data Cleaning'!D2 -> Boots | E2: ='Data Cleaning'!E2 -> Blue | F2: ='Data Cleaning'!F2 -> UK | G2: ='Data Cleaning'!G2 -> Online | H2: ='Data Cleaning'!H2 -> 112.4 | ... J2: ='Data Cleaning'!J2 -> 449.6
A3: ='Data Cleaning'!A3 -> S2 | B3: ='Data Cleaning'!B3 -> 45729 | C3: ='Data Cleaning'!C3 -> Skechers | D3: ='Data Cleaning'!D3 -> Boots | E3: ='Data Cleaning'!E3 -> Grey | F3: ='Data Cleaning'!F3 -> USA | G3: ='Data Cleaning'!G3 -> Mall | H3: ='Data Cleaning'!H3 -> 239.16 | ... J3: ='Data Cleaning'!J3 -> 956.64
A4: ='Data Cleaning'!A4 -> S3 | B4: ='Data Cleaning'!B4 -> 45874 | C4: ='Data Cleaning'!C4 -> Nike | D4: ='Data Cleaning'!D4 -> Running | E4: ='Data Cleaning'!E4 -> White | F4: ='Data Cleaning'!F4 -> UK | G4: ='Data Cleaning'!G4 -> Mall | H4: ='Data Cleaning'!H4 -> 191.04 | ... J4: ='Data Cleaning'!J4 -> 382.08
A5: ='Data Cleaning'!A5 -> S4 | B5: ='Data Cleaning'!B5 -> 45966 | C5: ='Data Cleaning'!C5 -> New Balance | D5: ='Data Cleaning'!D5 -> Casual | E5: ='Data Cleaning'!E5 -> Green | F5: ='Data Cleaning'!F5 -> UAE | G5: ='Data Cleaning'!G5 -> Mall | H5: ='Data Cleaning'!H5 -> 161.7 | ... J5: ='Data Cleaning'!J5 -> 161.7
A6: ='Data Cleaning'!A6 -> S5 | B6: ='Data Cleaning'!B6 -> 45937 | C6: ='Data Cleaning'!C6 -> Adidas | D6: ='Data Cleaning'!D6 -> Formal | E6: ='Data Cleaning'!E6 -> Grey | F6: ='Data Cleaning'!F6 -> France | G6: ='Data Cleaning'!G6 -> Online | H6: ='Data Cleaning'!H6 -> 64.32 | ... J6: ='Data Cleaning'!J6 -> 900.48
A7: ='Data Cleaning'!A7 -> S6 | B7: ='Data Cleaning'!B7 -> 45739 | C7: ='Data Cleaning'!C7 -> Puma | D7: ='Data Cleaning'!D7 -> Sports | E7: ='Data Cleaning'!E7 -> White | F7: ='Data Cleaning'!F7 -> UK | G7: ='Data Cleaning'!G7 -> Retail Store | H7: ='Data Cleaning'!H7 -> 64.32 | ... J7: ='Data Cleaning'!J7 -> 900.48
A8: ='Data Cleaning'!A8 -> S7 | B8: ='Data Cleaning'!B8 -> 45710 | C8: ='Data Cleaning'!C8 -> Reebok | D8: ='Data Cleaning'!D8 -> Running | E8: ='Data Cleaning'!E8 -> Blue | F8: ='Data Cleaning'!F8 -> Saudi Arabia | G8: ='Data Cleaning'!G8 -> Retail Store | H8: ='Data Cleaning'!H8 -> 42.78 | ... J8: ='Data Cleaning'!J8 -> 128.34
A9: ='Data Cleaning'!A9 -> S8 | B9: ='Data Cleaning'!B9 -> 45967 | C9: ='Data Cleaning'!C9 -> Nike | D9: ='Data Cleaning'!D9 -> Boots | E9: ='Data Cleaning'!E9 -> Red | F9: ='Data Cleaning'!F9 -> India | G9: ='Data Cleaning'!G9 -> Online | H9: ='Data Cleaning'!H9 -> 220.56 | ... J9: ='Data Cleaning'!J9 -> 1985.04
A10: ='Data Cleaning'!A10 -> S9 | B10: ='Data Cleaning'!B10 -> 45851 | C10: ='Data Cleaning'!C10 -> New Balance | D10: ='Data Cleaning'!D10 -> Sports | E10: ='Data Cleaning'!E10 -> Green | F10: ='Data Cleaning'!F10 -> India | G10: ='Data Cleaning'!G10 -> Retail Store | H10: ='Data Cleaning'!H10 -> 162.25 | ... J10: ='Data Cleaning'!J10 -> 486.75
A11: ='Data Cleaning'!A11 -> S10 | B11: ='Data Cleaning'!B11 -> 45953 | C11: ='Data Cleaning'!C11 -> Skechers | D11: ='Data Cleaning'!D11 -> Running | E11: ='Data Cleaning'!E11 -> Black | F11: ='Data Cleaning'!F11 -> UAE | G11: ='Data Cleaning'!G11 -> Online | H11: ='Data Cleaning'!H11 -> 185.78 | ... J11: ='Data Cleaning'!J11 -> 1300.46
A12: ='Data Cleaning'!A12 -> S11 | B12: ='Data Cleaning'!B12 -> 45806 | C12: ='Data Cleaning'!C12 -> Adidas | D12: ='Data Cleaning'!D12 -> Running | E12: ='Data Cleaning'!E12 -> Red | F12: ='Data Cleaning'!F12 -> France | G12: ='Data Cleaning'!G12 -> Retail Store | H12: ='Data Cleaning'!H12 -> 34.53 | ... J12: ='Data Cleaning'!J12 -> 103.59
A13: ='Data Cleaning'!A13 -> S12 | B13: ='Data Cleaning'!B13 -> 45983 | C13: ='Data Cleaning'!C13 -> Adidas | D13: ='Data Cleaning'!D13 -> Sports | E13: ='Data Cleaning'!E13 -> Blue | F13: ='Data Cleaning'!F13 -> UK | G13: ='Data Cleaning'!G13 -> Mall | H13: ='Data Cleaning'!H13 -> 243.38 | ... J13: ='Data Cleaning'!J13 -> 2920.56
... A1007: ='Data Cleaning'!A1007 -> S1000 | B1007: ='Data Cleaning'!B1007 -> 45899 | C1007: ='Data Cleaning'!C1007 -> Puma | D1007: ='Data Cleaning'!D1007 -> Casual | E1007: ='Data Cleaning'!E1007 -> Green | F1007: ='Data Cleaning'!F1007 -> India | G1007: ='Data Cleaning'!G1007 -> Online | H1007: ='Data Cleaning'!H1007 -> 128.12 | ... J1007: ='Data Cleaning'!J1007 -> 128.12

Sheet KPI
B1: KPI_Total Rvenue | D1: KPI_AVG Order Value | F1: KPI_Monthly Growth | J1: KPI_Best Country | N1: KPI_Best Month | R1: KPI_Top Monthly Growth
B2: Total Revenue | D2: AVG Revenue | F2: Helper Table | R2: Row Labels | S2: Sum of Revenue_USD | T2: MoM | V2: Row Labels | W2: Sum of Revenue_USD
B3: 1459848.6 | D3: 1451.1418 | F3: Row Labels | G3: Sum of Revenue_USD | H3: MoM(%) | J3: Row Labels | K3: Sum of Revenue_USD | N3: Row Labels | O3: Sum of Revenue_USD | R3: Jan | S3: 102989.92 | V3: Jan
F4: Jan | G4: 102989.92 | J4: UAE | K4: 240051.92 | N4: Okt | O4: 146726.46 | R4: Feb | S4: 128723.42 | T4: =(S4-S3)/S3 -> 0.24986426 | V4: Feb | W4: 0.24986426
B5: KPI_Total Transaction | D5: KPI_Total Sold | F5: Feb | G5: 128723.42 | H5: =(G5-G4)/G4 -> 0.24986426 | J5: USA | K5: 231784.48 | N5: Jul | O5: 140198.13 | R5: Mar | S5: 118450.74 | T5: =(S5-S4)/S4 -> -0.079804281 | V5: Mar | W5: -0.079804281
B6: Total Transaction | D6: Total Sold | F6: Mar | G6: 118450.74 | H6: =(G6-G5)/G5 -> -0.079804281 | J6: France | K6: 229435.45 | N6: Nov | O6: 131542.53 | R6: Apr | S6: 115753.37 | T6: =(S6-S5)/S5 -> -0.022772082 | V6: Apr | W6: -0.022772082
B7: 1006 | D7: 10651 | F7: Apr | G7: 115753.37 | H7: =(G7-G6)/G6 -> -0.022772082 | J7: Germany | K7: 202201.71 | N7: Feb | O7: 128723.42 | R7: Mei | S7: 125637.78 | T7: =(S7-S6)/S6 -> 0.085391985 | V7: Mei | W7: 0.085391985
B8: KPI_AVG per product | F8: Mei | G8: 125637.78 | H8: =(G8-G7)/G7 -> 0.085391985 | J8: Saudi Arabia | K8: 191782.7 | N8: Des | O8: 127951.48 | R8: Jun | S8: 126802.88 | T8: =(S8-S7)/S7 -> 0.0092734845 | V8: Jun | W8: 0.0092734845
B9: AVG Revenue Per Product | F9: Jun | G9: 126802.88 | H9: =(G9-G8)/G8 -> 0.0092734845 | J9: UK | K9: 186632.61 | N9: Jun | O9: 126802.88 | R9: Jul | S9: 140198.13 | T9: =(S9-S8)/S8 -> 0.10563837 | V9: Jul | W9: 0.10563837
B10: 137.06212 | F10: Jul | G10: 140198.13 | H10: =(G10-G9)/G9 -> 0.10563837 | J10: India | K10: 177959.76 | N10: Mei | O10: 125637.78 | R10: Agu | S10: 96240.75 | T10: =(S10-S9)/S9 -> -0.31353756 | V10: Agu | W10: -0.31353756
F11: Agu | G11: 96240.75 | H11: =(G11-G10)/G10 -> -0.31353756 | N11: Mar | O11: 118450.74 | R11: Sep | S11: 98831.17 | T11: =(S11-S10)/S10 -> 0.026916041 | V11: Sep | W11: 0.026916041
B12: KPI AVG Monthly Revenue | F12: Sep | G12: 98831.17 | H12: =(G12-G11)/G11 -> 0.026916041 | N12: Apr | O12: 115753.37 | R12: Okt | S12: 146726.46 | T12: =(S12-S11)/S11 -> 0.48461725 | V12: Okt | W12: 0.48461725
B13: Average Monthly Revenue | F13: Okt | G13: 146726.46 | H13: =(G13-G12)/G12 -> 0.48461725 | J13: Helper Table | N13: Jan | O13: 102989.92 | R13: Nov | S13: 131542.53 | T13: =(S13-S12)/S12 -> -0.10348461 | V13: Nov | W13: -0.10348461
B14: 121654.05 | F14: Nov | G14: 131542.53 | H14: =(G14-G13)/G13 -> -0.10348461 | J14: Country | K14: Revenue | L14: Best Country | N14: Sep | O14: 98831.17 | R14: Des | S14: 127951.48 | T14: =(S14-S13)/S13 -> -0.027299536 | V14: Des | W14: -0.027299536
F15: Des | G15: 127951.48 | H15: =(G15-G14)/G14 -> -0.027299536 | J15: France | K15: =IFERROR(VLOOKUP(J15,$J$4:$K$10,2,0),NA()) -> 229435.45 | L15: =IF(K15=MAX($K$15:$K$21),J15,0) -> 0 | N15: Agu | O15: 96240.75
J16: Germany | K16: =IFERROR(VLOOKUP(J16,$J$4:$K$10,2,0),NA()) -> 202201.71 | L16: =IF(K16=MAX($K$15:$K$21),J16,0) -> 0
J17: India | K17: =IFERROR(VLOOKUP(J17,$J$4:$K$10,2,0),NA()) -> 177959.76 | L17: =IF(K17=MAX($K$15:$K$21),J17,0) -> 0 | R17: Helper Table
F18: Pivot Dashboard | J18: Saudi Arabia | K18: =IFERROR(VLOOKUP(J18,$J$4:$K$10,2,0),NA()) -> 191782.7 | L18: =IF(K18=MAX($K$15:$K$21),J18,0) -> 0 | N18: Helper Table | R18: Month | S18: Revenue Growth | T18: Peak Month
F19: Row Labels | G19: Sum of Revenue_USD | J19: UAE | K19: =IFERROR(VLOOKUP(J19,$J$4:$K$10,2,0),NA()) -> 240051.92 | L19: =IF(K19=MAX($K$15:$K$21),J19,0) -> UAE | N19: Month | O19: Revenue | P19: Peak Month | R19: Jan | S19: =IFERROR(VLOOKUP(R19,$R$3:$T$14,3,0),0) -> 0 | T19: =IF(S19=MAX($S$19:$S$30),R19,0) -> 0 | V19: =IF(AND(W3=MAX($W$3:$W$12),W3>0),V3,0) -> 0
F20: Jan | G20: 102989.92 | H20: =VLOOKUP(F20,$F$4:$H$15,3,FALSE) -> 0 | J20: UK | K20: =IFERROR(VLOOKUP(J20,$J$4:$K$10,2,0),NA()) -> 186632.61 | L20: =IF(K20=MAX($K$15:$K$21),J20,0) -> 0 | N20: Jan | O20: =IFERROR(VLOOKUP(N20,$N$4:$O$15,2,0),NA()) -> 102989.92 | P20: =IF(O20=MAX($O$20:$O$31),N20,0) -> 0 | R20: Feb | S20: =IFERROR(VLOOKUP(R20,$R$3:$T$14,3,0),NA()) -> 0.24986426 | T20: =IF(S20=MAX($S$19:$S$30),R20,0) -> 0 | V20: =IF(W4=MAX($W$3:$W$12),V4,0) -> 0
F21: Feb | G21: 128723.42 | J21: USA | K21: =IFERROR(VLOOKUP(J21,$J$4:$K$10,2,0),NA()) -> 231784.48 | L21: =IF(K21=MAX($K$15:$K$21),J21,0) -> 0 | N21: Feb | O21: =IFERROR(VLOOKUP(N21,$N$4:$O$15,2,0),NA()) -> 128723.42 | P21: =IF(O21=MAX($O$20:$O$31),N21,0) -> 0 | R21: Mar | S21: =IFERROR(VLOOKUP(R21,$R$3:$T$14,3,0),NA()) -> -0.079804281 | T21: =IF(S21=MAX($S$19:$S$30),R21,0) -> 0 | V21: =IF(W5=MAX($W$3:$W$12),V5,0) -> 0
F22: Mar | G22: 118450.74 | H22: =IF(H20>=0, "▲ "&TEXT(H20,"0,00%"), "▼ "&TEXT(ABS(H20),"0,00%")) -> ▲ 0,00% | J22: Best Country | L22: {=INDEX(L15:L21,MATCH(TRUE,ISTEXT(L15:L21),0))} -> UAE | N22: Mar | O22: =IFERROR(VLOOKUP(N22,$N$4:$O$15,2,0),NA()) -> 118450.74 | P22: =IF(O22=MAX($O$20:$O$31),N22,0) -> 0 | R22: Apr | S22: =IFERROR(VLOOKUP(R22,$R$3:$T$14,3,0),NA()) -> -0.022772082 | T22: =IF(S22=MAX($S$19:$S$30),R22,0) -> 0 | V22: =IF(W6=MAX($W$3:$W$12),V6,0) -> 0
F23: Apr | G23: 115753.37 | N23: Apr | O23: =IFERROR(VLOOKUP(N23,$N$4:$O$15,2,0),NA()) -> 115753.37 | P23: =IF(O23=MAX($O$20:$O$31),N23,0) -> 0 | R23: Mei | S23: =IFERROR(VLOOKUP(R23,$R$3:$T$14,3,0),NA()) -> 0.085391985 | T23: =IF(S23=MAX($S$19:$S$30),R23,0) -> 0 | V23: =IF(W7=MAX($W$3:$W$12),V7,0) -> 0
F24: Mei | G24: 125637.78 | H24: =IF(IFERROR(H22,"No Growth")="No Growth","No Growth",H22) -> ▲ 0,00% | J24: Dashboard Best Country | L24: =IF(COUNTA($J$4:$J$10)=7,L22,J4) -> UAE | N24: Mei | O24: =IFERROR(VLOOKUP(N24,$N$4:$O$15,2,0),NA()) -> 125637.78 | P24: =IF(O24=MAX($O$20:$O$31),N24,0) -> 0 | R24: Jun | S24: =IFERROR(VLOOKUP(R24,$R$3:$T$14,3,0),NA()) -> 0.0092734845 | T24: =IF(S24=MAX($S$19:$S$30),R24,0) -> 0 | V24: =IF(W8=MAX($W$3:$W$12),V8,0) -> 0
F25: Jun | G25: 126802.88 | L25: =IF(L24=0,"No Country",L24) -> UAE | N25: Jun | O25: =IFERROR(VLOOKUP(N25,$N$4:$O$15,2,0),NA()) -> 126802.88 | P25: =IF(O25=MAX($O$20:$O$31),N25,0) -> 0 | R25: Jul | S25: =IFERROR(VLOOKUP(R25,$R$3:$T$14,3,0),NA()) -> 0.10563837 | T25: =IF(S25=MAX($S$19:$S$30),R25,0) -> 0 | V25: =IF(W9=MAX($W$3:$W$12),V9,0) -> 0
F26: Jul | G26: 140198.13 | N26: Jul | O26: =IFERROR(VLOOKUP(N26,$N$4:$O$15,2,0),NA()) -> 140198.13 | P26: =IF(O26=MAX($O$20:$O$31),N26,0) -> 0 | R26: Agu | S26: =IFERROR(VLOOKUP(R26,$R$3:$T$14,3,0),NA()) -> -0.31353756 | T26: =IF(S26=MAX($S$19:$S$30),R26,0) -> 0 | V26: =IF(W10=MAX($W$3:$W$12),V10,0) -> 0
F27: Agu | G27: 96240.75 | N27: Agu | O27: =IFERROR(VLOOKUP(N27,$N$4:$O$15,2,0),NA()) -> 96240.75 | P27: =IF(O27=MAX($O$20:$O$31),N27,0) -> 0 | R27: Sep | S27: =IFERROR(VLOOKUP(R27,$R$3:$T$14,3,0),NA()) -> 0.026916041 | T27: =IF(S27=MAX($S$19:$S$30),R27,0) -> 0 | V27: =IF(W11=MAX($W$3:$W$12),V11,0) -> 0
F28: Sep | G28: 98831.17 | N28: Sep | O28: =IFERROR(VLOOKUP(N28,$N$4:$O$15,2,0),NA()) -> 98831.17 | P28: =IF(O28=MAX($O$20:$O$31),N28,0) -> 0 | R28: Okt | S28: =IFERROR(VLOOKUP(R28,$R$3:$T$14,3,0),NA()) -> 0.48461725 | T28: =IF(S28=MAX($S$19:$S$30),R28,0) -> Okt | V28: =IF(W12=MAX($W$3:$W$12),V12,0) -> Okt
F29: Okt | G29: 146726.46 | N29: Okt | O29: =IFERROR(VLOOKUP(N29,$N$4:$O$15,2,0),NA()) -> 146726.46 | P29: =IF(O29=MAX($O$20:$O$31),N29,0) -> Okt | R29: Nov | S29: =IFERROR(VLOOKUP(R29,$R$3:$T$14,3,0),NA()) -> -0.10348461 | T29: =IF(S29=MAX($S$19:$S$30),R29,0) -> 0 | V29: =IF(W13=MAX($W$3:$W$12),V13,0) -> 0
F30: Nov | G30: 131542.53 | N30: Nov | O30: =IFERROR(VLOOKUP(N30,$N$4:$O$15,2,0),NA()) -> 131542.53 | P30: =IF(O30=MAX($O$20:$O$31),N30,0) -> 0 | R30: Des | S30: =IFERROR(VLOOKUP(R30,$R$3:$T$14,3,0),NA()) -> -0.027299536 | T30: =IF(S30=MAX($S$19:$S$30),R30,0) -> 0 | V30: =IF(W14=MAX($W$3:$W$12),V14,0) -> 0
F31: Des | G31: 127951.48 | N31: Des | O31: =IFERROR(VLOOKUP(N31,$N$4:$O$15,2,0),NA()) -> 127951.48 | P31: =IF(O31=MAX($O$20:$O$31),N31,0) -> 0 | R31: MoM Growth Peak Month | T31: {=INDEX(T19:T30,MATCH(TRUE,ISTEXT(T19:T30),0))} -> Okt | V31: {=INDEX(V19:V30,MATCH(TRUE,ISTEXT(V19:V30),0))} -> Okt
N32: Peak Month | P32: {=INDEX(P20:P31,MATCH(TRUE,ISTEXT(P20:P31),0))} -> Okt
R33: Top Month Growth | T33: =IF(V31=0,"No Month",V31) -> Okt | V33: =IF(IFERROR(V31,"No Month")="No Month","No Month",V31) -> Okt
N34: Dasboard Peak Month | P34: =IF(COUNTA(N4:N15)=12,P32,N4) -> Okt | T34: =IF(V31="#N/A","No Month",V31) -> Okt
P35: =IF(P34=0,"No Month",P34) -> Okt

Sheet Pivot_Chart_Tables
B2: Monthy Revenue | G2: Monthly Growth Revenue
B3: Row Labels | C3: Sum of Revenue_USD | G3: Row Labels | H3: Sum of Revenue_USD | L3: India | M3: 2.4572294 | N3: Mei | O3: -0.71259747 | P3: Apr
B4: Jan | C4: 102989.92 | G4: Jan | I4: Jan | L4: UK | M4: 2.1387347 | N4: Agu | O4: -0.62250991 | P4: Jul
B5: Feb | C5: 128723.42 | G5: Feb | H5: 0.24986426 | I5: Feb | L5: Saudi Arabia | M5: 0.83902021 | N5: Feb | O5: -0.55103631 | P5: Jun
B6: Mar | C6: 118450.74 | G6: Mar | H6: -0.079804281 | I6: Mar | L6: Germany | M6: 4.0116014 | N6: Sep | O6: -0.73253928 | P6: Feb
B7: Apr | C7: 115753.37 | G7: Apr | H7: -0.022772082 | I7: Apr | L7: France | M7: 1.8697855 | N7: Okt | O7: -0.50083791 | P7: Nov
B8: Mei | C8: 125637.78 | G8: Mei | H8: 0.085391985 | I8: Mei | L8: USA | M8: 1.7608582 | N8: Des | O8: -0.72755785 | P8: Agu
B9: Jun | C9: 126802.88 | G9: Jun | H9: 0.0092734845 | I9: Jun | L9: UAE | M9: 2.9704875 | N9: Okt | O9: -0.7213239 | P9: Sep
B10: Jul | C10: 140198.13 | G10: Jul | H10: 0.10563837 | I10: Jul
B11: Agu | C11: 96240.75 | G11: Agu | H11: -0.31353756 | I11: Agu
B12: Sep | C12: 98831.17 | G12: Sep | H12: 0.026916041 | I12: Sep
B13: Okt | C13: 146726.46 | G13: Okt | H13: 0.48461725 | I13: Okt
B14: Nov | C14: 131542.53 | G14: Nov | H14: -0.10348461 | I14: Nov
B15: Des | C15: 127951.48 | G15: Des | H15: -0.027299536 | I15: Des
B17: Bulan | C17: Revenue | D17: MAX | E17: MIN | G17: Bulan | H17: Revenue Growth | I17: MAX | J17: MIN
B18: Jan | C18: =IFERROR(VLOOKUP(B18,$B$4:$C$15,2,0),0) -> 102989.92 | D18: =IF(C18=MAX($C$18:$C$29),C18,NA()) -> #N/A | E18: =IF(C18=MIN($C$18:$C$29),C18,NA()) -> #N/A | G18: Jan | H18: =IFERROR(VLOOKUP(G18,$G$4:$H$15,2,0),0) -> 0 | I18: =IF(H18=MAX($H$18:$H$29),H18,NA()) -> #N/A | J18: =IF(H18=MIN($H$18:$H$29),H18,NA()) -> #N/A
B19: Feb | C19: =IFERROR(VLOOKUP(B19,$B$4:$C$15,2,0),0) -> 128723.42 | D19: =IF(C19=MAX($C$18:$C$29),C19,NA()) -> #N/A | E19: =IF(C19=MIN($C$18:$C$29),C19,NA()) -> #N/A | G19: Feb | H19: =IFERROR(VLOOKUP(G19,$G$4:$H$15,2,0),0) -> 0.24986426 | I19: =IF(H19=MAX($H$18:$H$29),H19,NA()) -> #N/A | J19: =IF(H19=MIN($H$18:$H$29),H19,NA()) -> #N/A
B20: Mar | C20: =IFERROR(VLOOKUP(B20,$B$4:$C$15,2,0),0) -> 118450.74 | D20: =IF(C20=MAX($C$18:$C$29),C20,NA()) -> #N/A | E20: =IF(C20=MIN($C$18:$C$29),C20,NA()) -> #N/A | G20: Mar | H20: =IFERROR(VLOOKUP(G20,$G$4:$H$15,2,0),0) -> -0.079804281 | I20: =IF(H20=MAX($H$18:$H$29),H20,NA()) -> #N/A | J20: =IF(H20=MIN($H$18:$H$29),H20,NA()) -> #N/A
B21: Apr | C21: =IFERROR(VLOOKUP(B21,$B$4:$C$15,2,0),0) -> 115753.37 | D21: =IF(C21=MAX($C$18:$C$29),C21,NA()) -> #N/A | E21: =IF(C21=MIN($C$18:$C$29),C21,NA()) -> #N/A | G21: Apr | H21: =IFERROR(VLOOKUP(G21,$G$4:$H$15,2,0),0) -> -0.022772082 | I21: =IF(H21=MAX($H$18:$H$29),H21,NA()) -> #N/A | J21: =IF(H21=MIN($H$18:$H$29),H21,NA()) -> #N/A
B22: Mei | C22: =IFERROR(VLOOKUP(B22,$B$4:$C$15,2,0),0) -> 125637.78 | D22: =IF(C22=MAX($C$18:$C$29),C22,NA()) -> #N/A | E22: =IF(C22=MIN($C$18:$C$29),C22,NA()) -> #N/A | G22: Mei | H22: =IFERROR(VLOOKUP(G22,$G$4:$H$15,2,0),0) -> 0.085391985 | I22: =IF(H22=MAX($H$18:$H$29),H22,NA()) -> #N/A | J22: =IF(H22=MIN($H$18:$H$29),H22,NA()) -> #N/A
B23: Jun | C23: =IFERROR(VLOOKUP(B23,$B$4:$C$15,2,0),0) -> 126802.88 | D23: =IF(C23=MAX($C$18:$C$29),C23,NA()) -> #N/A | E23: =IF(C23=MIN($C$18:$C$29),C23,NA()) -> #N/A | G23: Jun | H23: =IFERROR(VLOOKUP(G23,$G$4:$H$15,2,0),0) -> 0.0092734845 | I23: =IF(H23=MAX($H$18:$H$29),H23,NA()) -> #N/A | J23: =IF(H23=MIN($H$18:$H$29),H23,NA()) -> #N/A
B24: Jul | C24: =IFERROR(VLOOKUP(B24,$B$4:$C$15,2,0),0) -> 140198.13 | D24: =IF(C24=MAX($C$18:$C$29),C24,NA()) -> #N/A | E24: =IF(C24=MIN($C$18:$C$29),C24,NA()) -> #N/A | G24: Jul | H24: =IFERROR(VLOOKUP(G24,$G$4:$H$15,2,0),0) -> 0.10563837 | I24: =IF(H24=MAX($H$18:$H$29),H24,NA()) -> #N/A | J24: =IF(H24=MIN($H$18:$H$29),H24,NA()) -> #N/A
B25: Agu | C25: =IFERROR(VLOOKUP(B25,$B$4:$C$15,2,0),0) -> 96240.75 | D25: =IF(C25=MAX($C$18:$C$29),C25,NA()) -> #N/A | E25: =IF(C25=MIN($C$18:$C$29),C25,NA()) -> 96240.75 | G25: Agu | H25: =IFERROR(VLOOKUP(G25,$G$4:$H$15,2,0),0) -> -0.31353756 | I25: =IF(H25=MAX($H$18:$H$29),H25,NA()) -> #N/A | J25: =IF(H25=MIN($H$18:$H$29),H25,NA()) -> -0.31353756
B26: Sep | C26: =IFERROR(VLOOKUP(B26,$B$4:$C$15,2,0),0) -> 98831.17 | D26: =IF(C26=MAX($C$18:$C$29),C26,NA()) -> #N/A | E26: =IF(C26=MIN($C$18:$C$29),C26,NA()) -> #N/A | G26: Sep | H26: =IFERROR(VLOOKUP(G26,$G$4:$H$15,2,0),0) -> 0.026916041 | I26: =IF(H26=MAX($H$18:$H$29),H26,NA()) -> #N/A | J26: =IF(H26=MIN($H$18:$H$29),H26,NA()) -> #N/A
B27: Okt | C27: =IFERROR(VLOOKUP(B27,$B$4:$C$15,2,0),0) -> 146726.46 | D27: =IF(C27=MAX($C$18:$C$29),C27,NA()) -> 146726.46 | E27: =IF(C27=MIN($C$18:$C$29),C27,NA()) -> #N/A | G27: Okt | H27: =IFERROR(VLOOKUP(G27,$G$4:$H$15,2,0),0) -> 0.48461725 | I27: =IF(H27=MAX($H$18:$H$29),H27,NA()) -> 0.48461725 | J27: =IF(H27=MIN($H$18:$H$29),H27,NA()) -> #N/A | Q27: f
B28: Nov | C28: =IFERROR(VLOOKUP(B28,$B$4:$C$15,2,0),0) -> 131542.53 | D28: =IF(C28=MAX($C$18:$C$29),C28,NA()) -> #N/A | E28: =IF(C28=MIN($C$18:$C$29),C28,NA()) -> #N/A | G28: Nov | H28: =IFERROR(VLOOKUP(G28,$G$4:$H$15,2,0),0) -> -0.10348461 | I28: =IF(H28=MAX($H$18:$H$29),H28,NA()) -> #N/A | J28: =IF(H28=MIN($H$18:$H$29),H28,NA()) -> #N/A | M28: Row Labels | N28: Sum of Revenue_USD
B29: Des | C29: =IFERROR(VLOOKUP(B29,$B$4:$C$15,2,0),0) -> 127951.48 | D29: =IF(C29=MAX($C$18:$C$29),C29,NA()) -> #N/A | E29: =IF(C29=MIN($C$18:$C$29),C29,NA()) -> #N/A | G29: Des | H29: =IFERROR(VLOOKUP(G29,$G$4:$H$15,2,0),0) -> -0.027299536 | I29: =IF(H29=MAX($H$18:$H$29),H29,NA()) -> #N/A | J29: =IF(H29=MIN($H$18:$H$29),H29,NA()) -> #N/A | M29: Jan | N29: 0.070548355
D30: =IF(C30=MAX($C$18:$C$29),C30,NA()) -> #N/A | E30: =IF(C30=MIN($C$18:$C$29),C30,NA()) -> #N/A | M30: Feb | N30: 0.088175868
B31: Country Revenue Performance | M31: Mar | N31: 0.081139056
B32: Row Labels | C32: Sum of Revenue_USD2 | D32: Sum of Revenue_USD | M32: Apr | N32: 0.079291351
B33: India | C33: 177959.76 | D33: 0.12190289 | M33: Mei | N33: 0.086062197
B34: UK | C34: 186632.61 | D34: 0.12784381 | M34: Jun | N34: 0.086860293
B35: Saudi Arabia | C35: 191782.7 | D35: 0.13137163 | M35: Jul | N35: 0.096036073
B36: Germany | C36: 202201.71 | D36: 0.13850868 | M36: Agu | N36: 0.065925157
B37: France | C37: 229435.45 | D37: 0.15716386 | M37: Sep | N37: 0.067699601
B38: USA | C38: 231784.48 | D38: 0.15877295 | M38: Okt | N38: 0.100508
B39: UAE | C39: 240051.92 | D39: 0.16443617 | M39: Nov | N39: 0.090106965
M40: Des | N40: 0.087647087
B42: Brands Revenue Performance
B43: Row Labels | C43: Sum of Revenue_USD | D43: Sum of Revenue_USD2
...

Sheet Pivot_Scatter
B1: Revenue x Total Transaction
B2: Row Labels | C2: Count of Sale_ID | D2: Sum of Revenue_USD | K2: Nilai Max
B3: Jan | C3: 70 | D3: 102989.92 | F3: Jan | G3: =IFERROR(VLOOKUP(F3,$B$3:$D$14,2,0),0) -> 70 | H3: =IFERROR(VLOOKUP(F3,$B$3:$D$14,3,0),0) -> 102989.92 | I3: {=IF(AND(H3=$K$3,ROW()=MIN(IF($H$3:$H$14=$K$3,ROW($H$3:$H$14)))),F3,"")} | K3: =_xlfn.AGGREGATE(4,5,H3:H14) -> 146726.46
B4: Feb | C4: 93 | D4: 128723.42 | F4: Feb | G4: =IFERROR(VLOOKUP(F4,$B$3:$D$14,2,0),0) -> 93 | H4: =IFERROR(VLOOKUP(F4,$B$3:$D$14,3,0),0) -> 128723.42 | I4: {=IF(AND(H4=$K$3,ROW()=MIN(IF($H$3:$H$14=$K$3,ROW($H$3:$H$14)))),F4,"")} | J4: =I4
B5: Mar | C5: 86 | D5: 118450.74 | F5: Mar | G5: =IFERROR(VLOOKUP(F5,$B$3:$D$14,2,0),0) -> 86 | H5: =IFERROR(VLOOKUP(F5,$B$3:$D$14,3,0),0) -> 118450.74 | I5: {=IF(AND(H5=$K$3,ROW()=MIN(IF($H$3:$H$14=$K$3,ROW($H$3:$H$14)))),F5,"")} | J5: =I5
B6: Apr | C6: 77 | D6: 115753.37 | F6: Apr | G6: =IFERROR(VLOOKUP(F6,$B$3:$D$14,2,0),0) -> 77 | H6: =IFERROR(VLOOKUP(F6,$B$3:$D$14,3,0),0) -> 115753.37 | I6: {=IF(AND(H6=$K$3,ROW()=MIN(IF($H$3:$H$14=$K$3,ROW($H$3:$H$14)))),F6,"")} | J6: =I6
B7: Mei | C7: 91 | D7: 125637.78 | F7: Mei | G7: =IFERROR(VLOOKUP(F7,$B$3:$D$14,2,0),0) -> 91 | H7: =IFERROR(VLOOKUP(F7,$B$3:$D$14,3,0),0) -> 125637.78 | I7: {=IF(AND(H7=$K$3,ROW()=MIN(IF($H$3:$H$14=$K$3,ROW($H$3:$H$14)))),F7,"")} | J7: =I7
B8: Jun | C8: 91 | D8: 126802.88 | F8: Jun | G8: =IFERROR(VLOOKUP(F8,$B$3:$D$14,2,0),0) -> 91 | H8: =IFERROR(VLOOKUP(F8,$B$3:$D$14,3,0),0) -> 126802.88 | I8: {=IF(AND(H8=$K$3,ROW()=MIN(IF($H$3:$H$14=$K$3,ROW($H$3:$H$14)))),F8,"")} | J8: =I8
B9: Jul | C9: 90 | D9: 140198.13 | F9: Jul | G9: =IFERROR(VLOOKUP(F9,$B$3:$D$14,2,0),0) -> 90 | H9: =IFERROR(VLOOKUP(F9,$B$3:$D$14,3,0),0) -> 140198.13 | I9: {=IF(AND(H9=$K$3,ROW()=MIN(IF($H$3:$H$14=$K$3,ROW($H$3:$H$14)))),F9,"")} | J9: =I9
B10: Agu | C10: 77 | D10: 96240.75 | F10: Agu | G10: =IFERROR(VLOOKUP(F10,$B$3:$D$14,2,0),0) -> 77 | H10: =IFERROR(VLOOKUP(F10,$B$3:$D$14,3,0),0) -> 96240.75 | I10: {=IF(AND(H10=$K$3,ROW()=MIN(IF($H$3:$H$14=$K$3,ROW($H$3:$H$14)))),F10,"")} | J10: =I10
B11: Sep | C11: 70 | D11: 98831.17 | F11: Sep | G11: =IFERROR(VLOOKUP(F11,$B$3:$D$14,2,0),0) -> 70 | H11: =IFERROR(VLOOKUP(F11,$B$3:$D$14,3,0),0) -> 98831.17 | I11: {=IF(AND(H11=$K$3,ROW()=MIN(IF($H$3:$H$14=$K$3,ROW($H$3:$H$14)))),F11,"")} | J11: =I11
B12: Okt | C12: 98 | D12: 146726.46 | F12: Okt | G12: =IFERROR(VLOOKUP(F12,$B$3:$D$14,2,0),0) -> 98 | H12: =IFERROR(VLOOKUP(F12,$B$3:$D$14,3,0),0) -> 146726.46 | I12: {=IF(AND(H12=$K$3,ROW()=MIN(IF($H$3:$H$14=$K$3,ROW($H$3:$H$14)))),F12,"")} -> Okt
B13: Nov | C13: 76 | D13: 131542.53 | F13: Nov | G13: =IFERROR(VLOOKUP(F13,$B$3:$D$14,2,0),0) -> 76 | H13: =IFERROR(VLOOKUP(F13,$B$3:$D$14,3,0),0) -> 131542.53 | I13: {=IF(AND(H13=$K$3,ROW()=MIN(IF($H$3:$H$14=$K$3,ROW($H$3:$H$14)))),F13,"")} | J13: =I13
B14: Des | C14: 87 | D14: 127951.48 | F14: Des | G14: =IFERROR(VLOOKUP(F14,$B$3:$D$14,2,0),0) -> 87 | H14: =IFERROR(VLOOKUP(F14,$B$3:$D$14,3,0),0) -> 127951.48 | I14: {=IF(AND(H14=$K$3,ROW()=MIN(IF($H$3:$H$14=$K$3,ROW($H$3:$H$14)))),F14,"")} | J14: =I14

Sheet Pivot_Heatmap
A1: Sum of Units_Sold | B1: Type of Shoes | J1: Sum of Units_Sold | K1: Type of Shoes | T1: Rank(Product) | U1: Products | V1: Number of Sold | X1: Top 5 Selling-Product | AF1: Total Revenue
A2: Brand | B2: Adidas | C2: New Balance | D2: Nike | E2: Puma | F2: Reebok | G2: Skechers | H2: Grand Total | J2: Brand | K2: Boots | L2: Casual | M2: Formal | N2: Running | O2: Sneakers | P2: Sports | Q2: Grand Total | T2: =_xlfn.RANK.EQ(V2,$V$2:$V$37,0)+COUNTIF($V$2:V2,V2)-1 -> 10 | U2: =$B$11&"-"&A12 -> Adidas-Boots | V2: =B12 -> 329 | X2: TOP | Y2: Product Name | Z2: Number of Sold | AA2: Number of Rank
A3: Boots | B3: 329 | C3: 386 | D3: 264 | E3: 299 | F3: 246 | G3: 343 | H3: 1867 | J3: White | K3: 266 | L3: 164 | M3: 228 | N3: 261 | O3: 387 | P3: 207 | Q3: 1513 | T3: =_xlfn.RANK.EQ(V3,$V$2:$V$37,0)+COUNTIF($V$2:V3,V3)-1 -> 29 | U3: =$B$11&"-"&A13 -> Adidas-Casual | V3: =B13 -> 252 | X3: 1 | Y3: =VLOOKUP(X3,$T$2:$V$37,2,0) -> Adidas-Sneakers | Z3: =VLOOKUP(X3,$T$2:$V$37,3,0) -> 438 | AA3: =COUNTIF($T$2:$T$37,1) -> 1
A4: Casual | B4: 252 | C4: 286 | D4: 231 | E4: 269 | F4: 370 | G4: 307 | H4: 1715 | J4: Red | K4: 339 | L4: 354 | M4: 245 | N4: 297 | O4: 264 | P4: 231 | Q4: 1730 | T4: =_xlfn.RANK.EQ(V4,$V$2:$V$37,0)+COUNTIF($V$2:V4,V4)-1 -> 19 | U4: =$B$11&"-"&A14 -> Adidas-Formal | V4: =B14 -> 291 | X4: 2 | Y4: =VLOOKUP(X4,$T$2:$V$37,2,0) -> Skechers-Running | Z4: =VLOOKUP(X4,$T$2:$V$37,3,0) -> 398 | AA4: =COUNTIF($T$2:$T$37,2) -> 1
A5: Formal | B5: 291 | C5: 351 | D5: 271 | E5: 374 | F5: 304 | G5: 301 | H5: 1892 | J5: Grey | K5: 376 | L5: 340 | M5: 289 | N5: 334 | O5: 356 | P5: 201 | Q5: 1896 | T5: =_xlfn.RANK.EQ(V5,$V$2:$V$37,0)+COUNTIF($V$2:V5,V5)-1 -> 15 | U5: =$B$11&"-"&A15 -> Adidas-Running | V5: =B15 -> 305 | X5: 3 | Y5: =VLOOKUP(X5,$T$2:$V$37,2,0) -> New Balance-Boots | Z5: =VLOOKUP(X5,$T$2:$V$37,3,0) -> 386 | AA5: =COUNTIF($T$2:$T$37,3) -> 1
A6: Running | B6: 305 | C6: 276 | D6: 181 | E6: 258 | F6: 256 | G6: 398 | H6: 1674 | J6: Green | K6: 256 | L6: 266 | M6: 434 | N6: 275 | O6: 322 | P6: 215 | Q6: 1768 | T6: =_xlfn.RANK.EQ(V6,$V$2:$V$37,0)+COUNTIF($V$2:V6,V6)-1 -> 1 | U6: =$B$11&"-"&A16 -> Adidas-Sneakers | V6: =B16 -> 438 | X6: 4 | Y6: =IFERROR(VLOOKUP(X6,$T$2:$V$37,2,0),"No-Product") -> Puma-Formal | Z6: =IFERROR(VLOOKUP(X6,$T$2:$V$37,3,0),0) -> 374 | AA6: =COUNTIF($T$2:$T$37,4) -> 1
A7: Sneakers | B7: 438 | C7: 324 | D7: 354 | E7: 256 | F7: 283 | G7: 343 | H7: 1998 | J7: Blue | K7: 360 | L7: 234 | M7: 329 | N7: 255 | O7: 380 | P7: 380 | Q7: 1938 | T7: =_xlfn.RANK.EQ(V7,$V$2:$V$37,0)+COUNTIF($V$2:V7,V7)-1 -> 32 | U7: =$B$11&"-"&A17 -> Adidas-Sports | V7: =B17 -> 238 | X7: 5 | Y7: =IFERROR(VLOOKUP(X7,$T$2:$V$37,2,0),"No-Product") -> Reebok-Casual | Z7: =IFERROR(VLOOKUP(X7,$T$2:$V$37,3,0),0) -> 370 | AA7: =COUNTIF($T$2:$T$37,5) -> 1
A8: Sports | B8: 238 | C8: 219 | D8: 170 | E8: 319 | F8: 241 | G8: 318 | H8: 1505 | J8: Black | K8: 270 | L8: 357 | M8: 367 | N8: 252 | O8: 289 | P8: 271 | Q8: 1806 | T8: =_xlfn.RANK.EQ(V8,$V$2:$V$37,0)+COUNTIF($V$2:V8,V8)-1 -> 3 | U8: =$C$11&"-"&A12 -> New Balance-Boots | V8: =C12 -> 386 | X8: 6 | Y8: =IFERROR(VLOOKUP(X8,$T$2:$V$37,2,0),"No-Product") -> Nike-Sneakers | Z8: =IFERROR(VLOOKUP(X8,$T$2:$V$37,3,0),0) -> 354 | AA8: =COUNTIF($T$2:$T$37,6) -> 1
T9: =_xlfn.RANK.EQ(V9,$V$2:$V$37,0)+COUNTIF($V$2:V9,V9)-1 -> 20 | U9: =$C$11&"-"&A13 -> New Balance-Casual | V9: =C13 -> 286 | X9: 7 | Y9: =IFERROR(VLOOKUP(X9,$T$2:$V$37,2,0),"No-Product") -> New Balance-Formal | Z9: =IFERROR(VLOOKUP(X9,$T$2:$V$37,3,0),0) -> 351 | AA9: =COUNTIF($T$2:$T$37,7) -> 1
T10: =_xlfn.RANK.EQ(V10,$V$2:$V$37,0)+COUNTIF($V$2:V10,V10)-1 -> 7 | U10: =$C$11&"-"&A14 -> New Balance-Formal | V10: =C14 -> 351 | X10: 8 | Y10: =IFERROR(VLOOKUP(X10,$T$2:$V$37,2,0),"No-Product") -> Skechers-Boots | Z10: =IFERROR(VLOOKUP(X10,$T$2:$V$37,3,0),0) -> 343 | AA10: =COUNTIF($T$2:$T$37,8) -> 1
B11: Adidas | C11: New Balance | D11: Nike | E11: Puma | F11: Reebok | G11: Skechers | H11: Total | K11: Boots | L11: Casual | M11: Formal | N11: Running | O11: Sneakers | P11: Sports | T11: =_xlfn.RANK.EQ(V11,$V$2:$V$37,0)+COUNTIF($V$2:V11,V11)-1 -> 22 | U11: =$C$11&"-"&A15 -> New Balance-Running | V11: =C15 -> 276 | X11: 9 | Y11: =IFERROR(VLOOKUP(X11,$T$2:$V$37,2,0),"No-Product") -> Skechers-Sneakers | Z11: =IFERROR(VLOOKUP(X11,$T$2:$V$37,3,0),0) -> 343 | AA11: =COUNTIF($T$2:$T$37,9) -> 1
A12: Boots | B12: =IFERROR(VLOOKUP($A$12,$A$3:$G$8,MATCH(B11,$A$2:$G$2,0),0),0) -> 329 | C12: =IFERROR(VLOOKUP($A$12,$A$3:$G$8,MATCH(C11,$A$2:$G$2,0),0),0) -> 386 | D12: =IFERROR(VLOOKUP($A$12,$A$3:$G$8,MATCH(D11,$A$2:$G$2,0),0),0) -> 264 | E12: =IFERROR(VLOOKUP($A$12,$A$3:$G$8,MATCH(E11,$A$2:$G$2,0),0),0) -> 299 | F12: =IFERROR(VLOOKUP($A$12,$A$3:$G$8,MATCH(F11,$A$2:$G$2,0),0),0) -> 246 | G12: =IFERROR(VLOOKUP($A$12,$A$3:$G$8,MATCH(G11,$A$2:$G$2,0),0),0) -> 343 | H12: =SUM(B12:G12) -> 1867 | J12: Black | K12: =IFERROR(VLOOKUP($J$12,$J$3:$P$8,MATCH(K11,$J$2:$P$2,0),0)," ") -> 270 | L12: =IFERROR(VLOOKUP($J$12,$J$3:$P$8,MATCH(L11,$J$2:$P$2,0),0)," ") -> 357 | M12: =IFERROR(VLOOKUP($J$12,$J$3:$P$8,MATCH(M11,$J$2:$P$2,0),0)," ") -> 367 | N12: =IFERROR(VLOOKUP($J$12,$J$3:$P$8,MATCH(N11,$J$2:$P$2,0),0)," ") -> 252 | O12: =IFERROR(VLOOKUP($J$12,$J$3:$P$8,MATCH(O11,$J$2:$P$2,0),0)," ") -> 289 | P12: =IFERROR(VLOOKUP($J$12,$J$3:$P$8,MATCH(P11,$J$2:$P$2,0),0)," ") -> 271 | T12: =_xlfn.RANK.EQ(V12,$V$2:$V$37,0)+COUNTIF($V$2:V12,V12)-1 -> 11 | U12: =$C$11&"-"&A16 -> New Balance-Sneakers | V12: =C16 -> 324 | X12: 10 | Y12: =IFERROR(VLOOKUP(X12,$T$2:$V$37,2,0),"No-Product") -> Adidas-Boots | Z12: =IFERROR(VLOOKUP(X12,$T$2:$V$37,3,0),0) -> 329 | AA12: =COUNTIF($T$2:$T$37,10) -> 1
A13: Casual | B13: =IFERROR(VLOOKUP($A$13,$A$3:$G$8,MATCH(B11,$A$2:$G$2,0),0),0) -> 252 | C13: =IFERROR(VLOOKUP($A$13,$A$3:$G$8,MATCH(C11,$A$2:$G$2,0),0),0) -> 286 | D13: =IFERROR(VLOOKUP($A$13,$A$3:$G$8,MATCH(D11,$A$2:$G$2,0),0),0) -> 231 | E13: =IFERROR(VLOOKUP($A$13,$A$3:$G$8,MATCH(E11,$A$2:$G$2,0),0),0) -> 269 | F13: =IFERROR(VLOOKUP($A$13,$A$3:$G$8,MATCH(F11,$A$2:$G$2,0),0),0) -> 370 | G13: =IFERROR(VLOOKUP($A$13,$A$3:$G$8,MATCH(G11,$A$2:$G$2,0),0),0) -> 307 | H13: =SUM(B13:G13) -> 1715 | J13: Blue | K13: =IFERROR(VLOOKUP($J$13,$J$3:$P$8,MATCH(K11,$J$2:$P$2,0),0),"") -> 360 | L13: =IFERROR(VLOOKUP($J$13,$J$3:$P$8,MATCH(L11,$J$2:$P$2,0),0),"") -> 234 | M13: =IFERROR(VLOOKUP($J$13,$J$3:$P$8,MATCH(M11,$J$2:$P$2,0),0),"") -> 329 | N13: =IFERROR(VLOOKUP($J$13,$J$3:$P$8,MATCH(N11,$J$2:$P$2,0),0),"") -> 255 | O13: =IFERROR(VLOOKUP($J$13,$J$3:$P$8,MATCH(O11,$J$2:$P$2,0),0),"") -> 380 | P13: =IFERROR(VLOOKUP($J$13,$J$3:$P$8,MATCH(P11,$J$2:$P$2,0),0),"") -> 380 | T13: =_xlfn.RANK.EQ(V13,$V$2:$V$37,0)+COUNTIF($V$2:V13,V13)-1 -> 34 | U13: =$C$11&"-"&A17 -> New Balance-Sports | V13: =C17 -> 219
A14: Formal | B14: =IFERROR(VLOOKUP($A$14,$A$3:$G$8,MATCH(B11,$A$2:$G$2,0),0),0) -> 291 | C14: =IFERROR(VLOOKUP($A$14,$A$3:$G$8,MATCH(C11,$A$2:$G$2,0),0),0) -> 351 | D14: =IFERROR(VLOOKUP($A$14,$A$3:$G$8,MATCH(D11,$A$2:$G$2,0),0),0) -> 271 | E14: =IFERROR(VLOOKUP($A$14,$A$3:$G$8,MATCH(E11,$A$2:$G$2,0),0),0) -> 374 | F14: =IFERROR(VLOOKUP($A$14,$A$3:$G$8,MATCH(F11,$A$2:$G$2,0),0),0) -> 304 | G14: =IFERROR(VLOOKUP($A$14,$A$3:$G$8,MATCH(G11,$A$2:$G$2,0),0),0) -> 301 | H14: =SUM(B14:G14) -> 1892 | J14: Green | K14: =IFERROR(VLOOKUP($J$14,$J$3:$P$8,MATCH(K11,$J$2:$P$2,0),0)," ") -> 256 | L14: =IFERROR(VLOOKUP($J$14,$J$3:$P$8,MATCH(L11,$J$2:$P$2,0),0)," ") -> 266 | M14: =IFERROR(VLOOKUP($J$14,$J$3:$P$8,MATCH(M11,$J$2:$P$2,0),0)," ") -> 434 | N14: =IFERROR(VLOOKUP($J$14,$J$3:$P$8,MATCH(N11,$J$2:$P$2,0),0)," ") -> 275 | O14: =IFERROR(VLOOKUP($J$14,$J$3:$P$8,MATCH(O11,$J$2:$P$2,0),0)," ") -> 322 | P14: =IFERROR(VLOOKUP($J$14,$J$3:$P$8,MATCH(P11,$J$2:$P$2,0),0)," ") -> 215 | T14: =_xlfn.RANK.EQ(V14,$V$2:$V$37,0)+COUNTIF($V$2:V14,V14)-1 -> 25 | U14: =$D$11&"-"&A12 -> Nike-Boots | V14: =D12 -> 264
A15: Running | B15: =IFERROR(VLOOKUP($A$15,$A$3:$G$8,MATCH(B11,$A$2:$G$2,0),0),0) -> 305 | C15: =IFERROR(VLOOKUP($A$15,$A$3:$G$8,MATCH(C11,$A$2:$G$2,0),0),0) -> 276 | D15: =IFERROR(VLOOKUP($A$15,$A$3:$G$8,MATCH(D11,$A$2:$G$2,0),0),0) -> 181 | E15: =IFERROR(VLOOKUP($A$15,$A$3:$G$8,MATCH(E11,$A$2:$G$2,0),0),0) -> 258 | F15: =IFERROR(VLOOKUP($A$15,$A$3:$G$8,MATCH(F11,$A$2:$G$2,0),0),0) -> 256 | G15: =IFERROR(VLOOKUP($A$15,$A$3:$G$8,MATCH(G11,$A$2:$G$2,0),0),0) -> 398 | H15: =SUM(B15:G15) -> 1674 | J15: White | K15: =IFERROR(VLOOKUP($J$15,$J$3:$P$8,MATCH(K11,$J$2:$P$2,0),0),"") -> 266 | L15: =IFERROR(VLOOKUP($J$15,$J$3:$P$8,MATCH(L11,$J$2:$P$2,0),0),"") -> 164 | M15: =IFERROR(VLOOKUP($J$15,$J$3:$P$8,MATCH(M11,$J$2:$P$2,0),0),"") -> 228 | N15: =IFERROR(VLOOKUP($J$15,$J$3:$P$8,MATCH(N11,$J$2:$P$2,0),0),"") -> 261 | O15: =IFERROR(VLOOKUP($J$15,$J$3:$P$8,MATCH(O11,$J$2:$P$2,0),0),"") -> 387 | P15: =IFERROR(VLOOKUP($J$15,$J$3:$P$8,MATCH(P11,$J$2:$P$2,0),0),"") -> 207 | T15: =_xlfn.RANK.EQ(V15,$V$2:$V$37,0)+COUNTIF($V$2:V15,V15)-1 -> 33 | U15: =$D$11&"-"&A13 -> Nike-Casual | V15: =D13 -> 231
A16: Sneakers | B16: =IFERROR(VLOOKUP($A$16,$A$3:$G$8,MATCH(B11,$A$2:$G$2,0),0),0) -> 438 | C16: =IFERROR(VLOOKUP($A$16,$A$3:$G$8,MATCH(C11,$A$2:$G$2,0),0),0) -> 324 | D16: =IFERROR(VLOOKUP($A$16,$A$3:$G$8,MATCH(D11,$A$2:$G$2,0),0),0) -> 354 | E16: =IFERROR(VLOOKUP($A$16,$A$3:$G$8,MATCH(E11,$A$2:$G$2,0),0),0) -> 256 | F16: =IFERROR(VLOOKUP($A$16,$A$3:$G$8,MATCH(F11,$A$2:$G$2,0),0),0) -> 283 | G16: =IFERROR(VLOOKUP($A$16,$A$3:$G$8,MATCH(G11,$A$2:$G$2,0),0),0) -> 343 | H16: =SUM(B16:G16) -> 1998 | J16: Red | K16: =IFERROR(VLOOKUP($J$16,$J$3:$P$8,MATCH(K11,$J$2:$P$2,0),0)," ") -> 339 | L16: =IFERROR(VLOOKUP($J$16,$J$3:$P$8,MATCH(L11,$J$2:$P$2,0),0)," ") -> 354 | M16: =IFERROR(VLOOKUP($J$16,$J$3:$P$8,MATCH(M11,$J$2:$P$2,0),0)," ") -> 245 | N16: =IFERROR(VLOOKUP($J$16,$J$3:$P$8,MATCH(N11,$J$2:$P$2,0),0)," ") -> 297 | O16: =IFERROR(VLOOKUP($J$16,$J$3:$P$8,MATCH(O11,$J$2:$P$2,0),0)," ") -> 264 | P16: =IFERROR(VLOOKUP($J$16,$J$3:$P$8,MATCH(P11,$J$2:$P$2,0),0)," ") -> 231 | T16: =_xlfn.RANK.EQ(V16,$V$2:$V$37,0)+COUNTIF($V$2:V16,V16)-1 -> 23 | U16: =$D$11&"-"&A14 -> Nike-Formal | V16: =D14 -> 271
A17: Sports | B17: =IFERROR(VLOOKUP($A$17,$A$3:$G$8,MATCH(B11,$A$2:$G$2,0),0),0) -> 238 | C17: =IFERROR(VLOOKUP($A$17,$A$3:$G$8,MATCH(C11,$A$2:$G$2,0),0),0) -> 219 | D17: =IFERROR(VLOOKUP($A$17,$A$3:$G$8,MATCH(D11,$A$2:$G$2,0),0),0) -> 170 | E17: =IFERROR(VLOOKUP($A$17,$A$3:$G$8,MATCH(E11,$A$2:$G$2,0),0),0) -> 319 | F17: =IFERROR(VLOOKUP($A$17,$A$3:$G$8,MATCH(F11,$A$2:$G$2,0),0),0) -> 241 | G17: =IFERROR(VLOOKUP($A$17,$A$3:$G$8,MATCH(G11,$A$2:$G$2,0),0),0) -> 318 | H17: =SUM(B17:G17) -> 1505 | J17: Grey | K17: =IFERROR(VLOOKUP($J$17,$J$3:$P$8,MATCH(K11,$J$2:$P$2,0),0),"") -> 376 | L17: =IFERROR(VLOOKUP($J$17,$J$3:$P$8,MATCH(L11,$J$2:$P$2,0),0),"") -> 340 | M17: =IFERROR(VLOOKUP($J$17,$J$3:$P$8,MATCH(M11,$J$2:$P$2,0),0),"") -> 289 | N17: =IFERROR(VLOOKUP($J$17,$J$3:$P$8,MATCH(N11,$J$2:$P$2,0),0),"") -> 334 | O17: =IFERROR(VLOOKUP($J$17,$J$3:$P$8,MATCH(O11,$J$2:$P$2,0),0),"") -> 356 | P17: =IFERROR(VLOOKUP($J$17,$J$3:$P$8,MATCH(P11,$J$2:$P$2,0),0),"") -> 201 | T17: =_xlfn.RANK.EQ(V17,$V$2:$V$37,0)+COUNTIF($V$2:V17,V17)-1 -> 35 | U17: =$D$11&"-"&A15 -> Nike-Running | V17: =D15 -> 181
T18: =_xlfn.RANK.EQ(V18,$V$2:$V$37,0)+COUNTIF($V$2:V18,V18)-1 -> 6 | U18: =$D$11&"-"&A16 -> Nike-Sneakers | V18: =D16 -> 354
A19: Sum of Revenue_USD | B19: Type of Shoes | T19: =_xlfn.RANK.EQ(V19,$V$2:$V$37,0)+COUNTIF($V$2:V19,V19)-1 -> 36 | U19: =$D$11&"-"&A17 -> Nike-Sports | V19: =D17 -> 170
A20: Brand | B20: Adidas | C20: New Balance | D20: Nike | E20: Puma | F20: Reebok | G20: Skechers | H20: Grand Total | T20: =_xlfn.RANK.EQ(V20,$V$2:$V$37,0)+COUNTIF($V$2:V20,V20)-1 -> 18 | U20: =$E$11&"-"&A12 -> Puma-Boots | V20: =E12 -> 299
A21: Boots | B21: 50183.71 | C21: 54219.25 | D21: 33979.63 | E21: 41299.51 | F21: 37884.75 | G21: 53257.61 | H21: 270824.46 | T21: =_xlfn.RANK.EQ(V21,$V$2:$V$37,0)+COUNTIF($V$2:V21,V21)-1 -> 24 | U21: =$E$11&"-"&A13 -> Puma-Casual | V21: =E13 -> 269
A22: Casual | B22: 34745.35 | C22: 39336.62 | D22: 26312.95 | E22: 41021.06 | F22: 50502.64 | G22: 31317.16 | H22: 223235.78 | T22: =_xlfn.RANK.EQ(V22,$V$2:$V$37,0)+COUNTIF($V$2:V22,V22)-1 -> 4 | U22: =$E$11&"-"&A14 -> Puma-Formal | V22: =E14 -> 374
A23: Formal | B23: 38554.06 | C23: 50619.07 | D23: 29066.22 | E23: 40568.22 | F23: 40580.98 | G23: 47382.46 | H23: 246771.01 | T23: =_xlfn.RANK.EQ(V23,$V$2:$V$37,0)+COUNTIF($V$2:V23,V23)-1 -> 26 | U23: =$E$11&"-"&A15 -> Puma-Running | V23: =E15 -> 258
A24: Running | B24: 37825.12 | C24: 38833.17 | D24: 29991.47 | E24: 31821.07 | F24: 37668.19 | G24: 54421.17 | H24: 230560.19 | T24: =_xlfn.RANK.EQ(V24,$V$2:$V$37,0)+COUNTIF($V$2:V24,V24)-1 -> 27 | U24: =$E$11&"-"&A16 -> Puma-Sneakers | V24: =E16 -> 256
A25: Sneakers | B25: 63679.1 | C25: 50486.65 | D25: 47911.53 | E25: 43394.23 | F25: 39802.64 | G25: 39297.29 | H25: 284571.44 | T25: =_xlfn.RANK.EQ(V25,$V$2:$V$37,0)+COUNTIF($V$2:V25,V25)-1 -> 12 | U25: =$E$11&"-"&A17 -> Puma-Sports | V25: =E17 -> 319
A26: Sports | B26: 32051.7 | C26: 28136.92 | D26: 25508.35 | E26: 40951.69 | F26: 32387.74 | G26: 44849.35 | H26: 203885.75 | T26: =_xlfn.RANK.EQ(V26,$V$2:$V$37,0)+COUNTIF($V$2:V26,V26)-1 -> 30 | U26: =$F$11&"-"&A12 -> Reebok-Boots | V26: =F12 -> 246
T27: =_xlfn.RANK.EQ(V27,$V$2:$V$37,0)+COUNTIF($V$2:V27,V27)-1 -> 5 | U27: =$F$11&"-"&A13 -> Reebok-Casual | V27: =F13 -> 370
B28: Adidas | C28: New Balance | D28: Nike | E28: Puma | F28: Reebok | G28: Skechers | T28: =_xlfn.RANK.EQ(V28,$V$2:$V$37,0)+COUNTIF($V$2:V28,V28)-1 -> 16 | U28: =$F$11&"-"&A14 -> Reebok-Formal | V28: =F14 -> 304
A29: Boots | B29: =IFERROR(VLOOKUP($A$29,$A$21:$G$26,MATCH(B28,$A$20:$G$20,0),0),) -> 50183.71 | C29: =IFERROR(VLOOKUP($A$29,$A$21:$G$26,MATCH(C28,$A$20:$G$20,0),0),) -> 54219.25 | D29: =IFERROR(VLOOKUP($A$29,$A$21:$G$26,MATCH(D28,$A$20:$G$20,0),0),) -> 33979.63 | E29: =IFERROR(VLOOKUP($A$29,$A$21:$G$26,MATCH(E28,$A$20:$G$20,0),0),) -> 41299.51 | F29: =IFERROR(VLOOKUP($A$29,$A$21:$G$26,MATCH(F28,$A$20:$G$20,0),0),) -> 37884.75 | G29: =IFERROR(VLOOKUP($A$29,$A$21:$G$26,MATCH(G28,$A$20:$G$20,0),0),) -> 53257.61 | T29: =_xlfn.RANK.EQ(V29,$V$2:$V$37,0)+COUNTIF($V$2:V29,V29)-1 -> 28 | U29: =$F$11&"-"&A15 -> Reebok-Running | V29: =F15 -> 256
A30: Casual | B30: =IFERROR(VLOOKUP($A$30,$A$21:$G$26,MATCH(B28,$A$20:$G$20,0),0),) -> 34745.35 | C30: =IFERROR(VLOOKUP($A$30,$A$21:$G$26,MATCH(C28,$A$20:$G$20,0),0),) -> 39336.62 | D30: =IFERROR(VLOOKUP($A$30,$A$21:$G$26,MATCH(D28,$A$20:$G$20,0),0),) -> 26312.95 | E30: =IFERROR(VLOOKUP($A$30,$A$21:$G$26,MATCH(E28,$A$20:$G$20,0),0),) -> 41021.06 | F30: =IFERROR(VLOOKUP($A$30,$A$21:$G$26,MATCH(F28,$A$20:$G$20,0),0),) -> 50502.64 | G30: =IFERROR(VLOOKUP($A$30,$A$21:$G$26,MATCH(G28,$A$20:$G$20,0),0),) -> 31317.16 | T30: =_xlfn.RANK.EQ(V30,$V$2:$V$37,0)+COUNTIF($V$2:V30,V30)-1 -> 21 | U30: =$F$11&"-"&A16 -> Reebok-Sneakers | V30: =F16 -> 283
A31: Formal | B31: =IFERROR(VLOOKUP($A$31,$A$21:$G$26,MATCH(B28,$A$20:$G$20,0),0),) -> 38554.06 | C31: =IFERROR(VLOOKUP($A$31,$A$21:$G$26,MATCH(C28,$A$20:$G$20,0),0),) -> 50619.07 | D31: =IFERROR(VLOOKUP($A$31,$A$21:$G$26,MATCH(D28,$A$20:$G$20,0),0),) -> 29066.22 | E31: =IFERROR(VLOOKUP($A$31,$A$21:$G$26,MATCH(E28,$A$20:$G$20,0),0),) -> 40568.22 | F31: =IFERROR(VLOOKUP($A$31,$A$21:$G$26,MATCH(F28,$A$20:$G$20,0),0),) -> 40580.98 | G31: =IFERROR(VLOOKUP($A$31,$A$21:$G$26,MATCH(G28,$A$20:$G$20,0),0),) -> 47382.46 | T31: =_xlfn.RANK.EQ(V31,$V$2:$V$37,0)+COUNTIF($V$2:V31,V31)-1 -> 31 | U31: =$F$11&"-"&A17 -> Reebok-Sports | V31: =F17 -> 241
A32: Running | B32: =IFERROR(VLOOKUP($A$32,$A$21:$G$26,MATCH(B28,$A$20:$G$20,0),0),) -> 37825.12 | C32: =IFERROR(VLOOKUP($A$32,$A$21:$G$26,MATCH(C28,$A$20:$G$20,0),0),) -> 38833.17 | D32: =IFERROR(VLOOKUP($A$32,$A$21:$G$26,MATCH(D28,$A$20:$G$20,0),0),) -> 29991.47 | E32: =IFERROR(VLOOKUP($A$32,$A$21:$G$26,MATCH(E28,$A$20:$G$20,0),0),) -> 31821.07 | F32: =IFERROR(VLOOKUP($A$32,$A$21:$G$26,MATCH(F28,$A$20:$G$20,0),0),) -> 37668.19 | G32: =IFERROR(VLOOKUP($A$32,$A$21:$G$26,MATCH(G28,$A$20:$G$20,0),0),) -> 54421.17 | T32: =_xlfn.RANK.EQ(V32,$V$2:$V$37,0)+COUNTIF($V$2:V32,V32)-1 -> 8 | U32: =$G$11&"-"&A12 -> Skechers-Boots | V32: =G12 -> 343
A33: Sneakers | B33: =IFERROR(VLOOKUP($A$33,$A$21:$G$26,MATCH(B28,$A$20:$G$20,0),0),) -> 63679.1 | C33: =IFERROR(VLOOKUP($A$33,$A$21:$G$26,MATCH(C28,$A$20:$G$20,0),0),) -> 50486.65 | D33: =IFERROR(VLOOKUP($A$33,$A$21:$G$26,MATCH(D28,$A$20:$G$20,0),0),) -> 47911.53 | E33: =IFERROR(VLOOKUP($A$33,$A$21:$G$26,MATCH(E28,$A$20:$G$20,0),0),) -> 43394.23 | F33: =IFERROR(VLOOKUP($A$33,$A$21:$G$26,MATCH(F28,$A$20:$G$20,0),0),) -> 39802.64 | G33: =IFERROR(VLOOKUP($A$33,$A$21:$G$26,MATCH(G28,$A$20:$G$20,0),0),) -> 39297.29 | T33: =_xlfn.RANK.EQ(V33,$V$2:$V$37,0)+COUNTIF($V$2:V33,V33)-1 -> 14 | U33: =$G$11&"-"&A13 -> Skechers-Casual | V33: =G13 -> 307
A34: Sports | B34: =IFERROR(VLOOKUP($A$34,$A$21:$G$26,MATCH(B28,$A$20:$G$20,0),0),) -> 32051.7 | C34: =IFERROR(VLOOKUP($A$34,$A$21:$G$26,MATCH(C28,$A$20:$G$20,0),0),) -> 28136.92 | D34: =IFERROR(VLOOKUP($A$34,$A$21:$G$26,MATCH(D28,$A$20:$G$20,0),0),) -> 25508.35 | E34: =IFERROR(VLOOKUP($A$34,$A$21:$G$26,MATCH(E28,$A$20:$G$20,0),0),) -> 40951.69 | F34: =IFERROR(VLOOKUP($A$34,$A$21:$G$26,MATCH(F28,$A$20:$G$20,0),0),) -> 32387.74 | G34: =IFERROR(VLOOKUP($A$34,$A$21:$G$26,MATCH(G28,$A$20:$G$20,0),0),) -> 44849.35 | T34: =_xlfn.RANK.EQ(V34,$V$2:$V$37,0)+COUNTIF($V$2:V34,V34)-1 -> 17 | U34: =$G$11&"-"&A14 -> Skechers-Formal | V34: =G14 -> 301
T35: =_xlfn.RANK.EQ(V35,$V$2:$V$37,0)+COUNTIF($V$2:V35,V35)-1 -> 2 | U35: =$G$11&"-"&A15 -> Skechers-Running | V35: =G15 -> 398
T36: =_xlfn.RANK.EQ(V36,$V$2:$V$37,0)+COUNTIF($V$2:V36,V36)-1 -> 9 | U36: =$G$11&"-"&A16 -> Skechers-Sneakers | V36: =G16 -> 343
T37: =_xlfn.RANK.EQ(V37,$V$2:$V$37,0)+COUNTIF($V$2:V37,V37)-1 -> 13 | U37: =$G$11&"-"&A17 -> Skechers-Sports | V37: =G17 -> 318
U38: =COUNTA(U2:U37) -> 36
A40: Sum of AVG per Product | B40: Type of Shoes
A41: Brand | B41: Adidas | C41: New Balance | D41: Nike | E41: Puma | F41: Reebok | G41: Skechers
...

Sheet Data Analysis
A1: Sale_ID | B1: Date | C1: Brand | D1: Shoe_Type | E1: Color | F1: Country | G1: Sales_Channel | H1: Price_USD | I1: Units_Sold | J1: Revenue_USD | K1: Day
A2: S1 | B2: 45985 | C2: Nike | D2: Boots | E2: Blue | F2: UK | G2: Online | H2: 112.4 | I2: 4 | J2: 449.6 | K2: =TEXT(B2,"dddd") -> Senin | M2: Months | N2: Total Transaction | O2: Total Units Sold | Q2: Months | R2: AVG Rev per Transaction | S2: AVG Rev per Product | U2: Months | V2: Total Revenue | X2: Months | Y2: Total Transaction | Z2: Total Revenue
A3: S2 | B3: 45729 | C3: Skechers | D3: Boots | E3: Grey | F3: USA | G3: Mall | H3: 239.16 | I3: 4 | J3: 956.64 | K3: =TEXT(B3,"dddd") -> Kamis | M3: Jan | N3: 70 | O3: 747 | Q3: Jan | R3: 1471.2846 | S3: 137.87138 | U3: Jan | V3: 102989.92 | X3: Jan | Y3: 70 | Z3: 102989.92
A4: S3 | B4: 45874 | C4: Nike | D4: Running | E4: White | F4: UK | G4: Mall | H4: 191.04 | I4: 2 | J4: 382.08 | K4: =TEXT(B4,"dddd") -> Selasa | M4: Feb | N4: 93 | O4: 988 | Q4: Feb | R4: 1384.1228 | S4: 130.28686 | U4: Feb | V4: 128723.42 | X4: Feb | Y4: 93 | Z4: 128723.42
A5: S4 | B5: 45966 | C5: New Balance | D5: Casual | E5: Green | F5: UAE | G5: Mall | H5: 161.7 | I5: 1 | J5: 161.7 | K5: =TEXT(B5,"dddd") -> Rabu | M5: Mar | N5: 86 | O5: 869 | Q5: Mar | R5: 1377.3342 | S5: 136.30695 | U5: Mar | V5: 118450.74 | X5: Mar | Y5: 86 | Z5: 118450.74
A6: S5 | B6: 45937 | C6: Adidas | D6: Formal | E6: Grey | F6: France | G6: Online | H6: 64.32 | I6: 14 | J6: 900.48 | K6: =TEXT(B6,"dddd") -> Selasa | M6: Apr | N6: 77 | O6: 819 | Q6: Apr | R6: 1503.2905 | S6: 141.33501 | U6: Apr | V6: 115753.37 | X6: Apr | Y6: 77 | Z6: 115753.37
A7: S6 | B7: 45739 | C7: Puma | D7: Sports | E7: White | F7: UK | G7: Retail Store | H7: 64.32 | I7: 14 | J7: 900.48 | K7: =TEXT(B7,"dddd") -> Minggu | M7: Mei | N7: 91 | O7: 911 | Q7: Mei | R7: 1380.6349 | S7: 137.91194 | U7: Mei | V7: 125637.78 | X7: Mei | Y7: 91 | Z7: 125637.78
A8: S7 | B8: 45710 | C8: Reebok | D8: Running | E8: Blue | F8: Saudi Arabia | G8: Retail Store | H8: 42.78 | I8: 3 | J8: 128.34 | K8: =TEXT(B8,"dddd") -> Sabtu | M8: Jun | N8: 91 | O8: 982 | Q8: Jun | R8: 1393.4382 | S8: 129.12717 | U8: Jun | V8: 126802.88 | X8: Jun | Y8: 91 | Z8: 126802.88
A9: S8 | B9: 45967 | C9: Nike | D9: Boots | E9: Red | F9: India | G9: Online | H9: 220.56 | I9: 9 | J9: 1985.04 | K9: =TEXT(B9,"dddd") -> Kamis | M9: Jul | N9: 90 | O9: 1039 | Q9: Jul | R9: 1557.757 | S9: 134.93564 | U9: Jul | V9: 140198.13 | X9: Jul | Y9: 90 | Z9: 140198.13
A10: S9 | B10: 45851 | C10: New Balance | D10: Sports | E10: Green | F10: India | G10: Retail Store | H10: 162.25 | I10: 3 | J10: 486.75 | K10: =TEXT(B10,"dddd") -> Minggu | M10: Agu | N10: 77 | O10: 666 | Q10: Agu | R10: 1249.8799 | S10: 144.50563 | U10: Agu | V10: 96240.75 | X10: Agu | Y10: 77 | Z10: 96240.75
A11: S10 | B11: 45953 | C11: Skechers | D11: Running | E11: Black | F11: UAE | G11: Online | H11: 185.78 | I11: 7 | J11: 1300.46 | K11: =TEXT(B11,"dddd") -> Kamis | M11: Sep | N11: 70 | O11: 752 | Q11: Sep | R11: 1411.8739 | S11: 131.42443 | U11: Sep | V11: 98831.17 | X11: Sep | Y11: 70 | Z11: 98831.17
A12: S11 | B12: 45806 | C12: Adidas | D12: Running | E12: Red | F12: France | G12: Retail Store | H12: 34.53 | I12: 3 | J12: 103.59 | K12: =TEXT(B12,"dddd") -> Kamis | M12: Okt | N12: 98 | O12: 1023 | Q12: Okt | R12: 1497.2088 | S12: 143.42762 | U12: Okt | V12: 146726.46 | X12: Okt | Y12: 98 | Z12: 146726.46
A13: S12 | B13: 45983 | C13: Adidas | D13: Sports | E13: Blue | F13: UK | G13: Mall | H13: 243.38 | I13: 12 | J13: 2920.56 | K13: =TEXT(B13,"dddd") -> Sabtu | M13: Nov | N13: 76 | O13: 849 | Q13: Nov | R13: 1730.8228 | S13: 154.9382 | U13: Nov | V13: 131542.53 | X13: Nov | Y13: 76 | Z13: 131542.53
A14: S13 | B14: 45794 | C14: New Balance | D14: Boots | E14: White | F14: India | G14: Mall | H14: 213.14 | I14: 3 | J14: 639.42 | K14: =TEXT(B14,"dddd") -> Sabtu | M14: Des | N14: 87 | O14: 1006 | Q14: Des | R14: 1470.7067 | S14: 127.18835 | U14: Des | V14: 127951.48 | X14: Des | Y14: 87 | Z14: 127951.48
A15: S14 | B15: 45783 | C15: Reebok | D15: Formal | E15: Blue | F15: UAE | G15: Mall | H15: 76.71 | I15: 6 | J15: 460.26 | K15: =TEXT(B15,"dddd") -> Selasa
A16: S15 | B16: 45943 | C16: Skechers | D16: Sports | E16: Black | F16: UK | G16: Online | H16: 70 | I16: 8 | J16: 560 | K16: =TEXT(B16,"dddd") -> Senin | X16: Correlation
A17: S16 | B17: 45819 | C17: Puma | D17: Running | E17: White | F17: India | G17: Mall | H17: 70.35 | I17: 13 | J17: 914.55 | K17: =TEXT(B17,"dddd") -> Rabu | Y17: AVG Rev per Transaction | Z17: Avg Rev per Product | AA17: Total Transactions | AB17: Total Units Sold | AC17: Total Revenue | AE17: Rank | AF17: Revenue Driver | AG17: Person Correlation | AH17: Interpretation
A18: S17 | B18: 45819 | C18: Skechers | D18: Formal | E18: Red | F18: UAE | G18: Retail Store | H18: 96.93 | I18: 7 | J18: 678.51 | K18: =TEXT(B18,"dddd") -> Rabu | X18: AVG Rev per Transaction | Y18: 1 | AE18: 1 | AF18: Total Units Sold | AG18: 0.91140571 | AH18: Very Strong Positive Correlation
A19: S18 | B19: 45731 | C19: Adidas | D19: Casual | E19: Green | F19: India | G19: Mall | H19: 145.45 | I19: 9 | J19: 1309.05 | K19: =TEXT(B19,"dddd") -> Sabtu | X19: Avg Rev per Product | Y19: 0.46187784 | Z19: 1 | AE19: 2 | AF19: Total Transaction | AG19: 0.80517555 | AH19: Very Strong Positive Correlation
A20: S19 | B20: 45792 | C20: Reebok | D20: Sneakers | E20: Red | F20: France | G20: Online | H20: 125.03 | I20: 19 | J20: 2375.57 | K20: =TEXT(B20,"dddd") -> Kamis | X20: Total Transactions | Y20: -0.099630766 | Z20: -0.27296926 | AA20: 1 | AE20: 3 | AF20: AVG per Transaction | AG20: 0.50821678 | AH20: Moderate Positive Correlation
A21: S20 | B21: 45728 | C21: Reebok | D21: Running | E21: Black | F21: Saudi Arabia | G21: Online | H21: 94.07 | I21: 17 | J21: 1599.19 | K21: =TEXT(B21,"dddd") -> Rabu | X21: Total Units Sold | Y21: 0.27768042 | Z21: -0.37507135 | AA21: 0.86118782 | AB21: 1 | AE21: 4 | AF21: AVG per Product | AG21: 0.037296789 | AH21: Very Weak/Negligible Correlation
A22: S21 | B22: 45736 | C22: Skechers | D22: Formal | E22: Grey | F22: USA | G22: Retail Store | H22: 164.61 | I22: 6 | J22: 987.66 | K22: =TEXT(B22,"dddd") -> Kamis | X22: Total Revenue | Y22: 0.50821678 | Z22: 0.037296789 | AA22: 0.80517555 | AB22: 0.91140571 | AC22: 1
A23: S22 | B23: 45853 | C23: Reebok | D23: Sneakers | E23: Blue | F23: India | G23: Online | H23: 60.69 | I23: 20 | J23: 1213.8 | K23: =TEXT(B23,"dddd") -> Selasa
A24: S23 | B24: 46006 | C24: Skechers | D24: Sneakers | E24: Blue | F24: Saudi Arabia | G24: Mall | H24: 94.27 | I24: 4 | J24: 377.08 | K24: =TEXT(B24,"dddd") -> Senin
A25: S24 | B25: 45832 | C25: Puma | D25: Formal | E25: White | F25: Germany | G25: Online | H25: 110.6 | I25: 4 | J25: 442.4 | K25: =TEXT(B25,"dddd") -> Selasa | X25: SLR
A26: S25 | B26: 45792 | C26: Adidas | D26: Sneakers | E26: Black | F26: Saudi Arabia | G26: Mall | H26: 130.34 | I26: 17 | J26: 2215.78 | K26: =TEXT(B26,"dddd") -> Kamis | X26: SUMMARY OUTPUT
A27: S26 | B27: 45810 | C27: New Balance | D27: Casual | E27: White | F27: France | G27: Online | H27: 202.74 | I27: 17 | J27: 3446.58 | K27: =TEXT(B27,"dddd") -> Senin
A28: S27 | B28: 45934 | C28: Nike | D28: Sneakers | E28: Blue | F28: Germany | G28: Online | H28: 73.93 | I28: 17 | J28: 1256.81 | K28: =TEXT(B28,"dddd") -> Sabtu | X28: Regression Statistics
A29: S28 | B29: 45715 | C29: Puma | D29: Casual | E29: Black | F29: UK | G29: Mall | H29: 143.13 | I29: 12 | J29: 1717.56 | K29: =TEXT(B29,"dddd") -> Kamis | X29: Multiple R | Y29: 0.91140571
A30: S29 | B30: 45698 | C30: Skechers | D30: Formal | E30: Black | F30: Saudi Arabia | G30: Mall | H30: 160.33 | I30: 3 | J30: 480.99 | K30: =TEXT(B30,"dddd") -> Senin | X30: R Square | Y30: 0.83066038
A31: S30 | B31: 45722 | C31: Skechers | D31: Formal | E31: Grey | F31: UK | G31: Retail Store | H31: 40.22 | I31: 5 | J31: 201.1 | K31: =TEXT(B31,"dddd") -> Kamis | X31: Adjusted R Square | Y31: 0.81372641
A32: S31 | B32: 45928 | C32: Reebok | D32: Casual | E32: Grey | F32: Saudi Arabia | G32: Mall | H32: 163.66 | I32: 20 | J32: 3273.2 | K32: =TEXT(B32,"dddd") -> Minggu | X32: Standard Error | Y32: 6839.5382
